log/output_500_2021_GRU_gpu2.log
wandb: Currently logged in as: pqy000 (pqythu). Use `wandb login --relogin` to force relogin
GPU device ID: 2
newdata/500_2021.npy
0
2024-09-07 11:22:39.664190: I tensorflow/core/platform/cpu_feature_guard.cc:193] This TensorFlow binary is optimized with oneAPI Deep Neural Network Library (oneDNN) to use the following CPU instructions in performance-critical operations:  AVX2 FMA
To enable them in other operations, rebuild TensorFlow with the appropriate compiler flags.
2024-09-07 11:22:40.925519: W tensorflow/compiler/xla/stream_executor/platform/default/dso_loader.cc:64] Could not load dynamic library 'libnvinfer.so.7'; dlerror: libnvinfer.so.7: cannot open shared object file: No such file or directory; LD_LIBRARY_PATH: /opt/cudnn/lib64:/usr/local/cuda/lib64
2024-09-07 11:22:40.925624: W tensorflow/compiler/xla/stream_executor/platform/default/dso_loader.cc:64] Could not load dynamic library 'libnvinfer_plugin.so.7'; dlerror: libnvinfer_plugin.so.7: cannot open shared object file: No such file or directory; LD_LIBRARY_PATH: /opt/cudnn/lib64:/usr/local/cuda/lib64
2024-09-07 11:22:40.925639: W tensorflow/compiler/tf2tensorrt/utils/py_utils.cc:38] TF-TRT Warning: Cannot dlopen some TensorRT libraries. If you would like to use Nvidia GPU with TensorRT, please make sure the missing libraries mentioned above are installed properly.
wandb: wandb version 0.17.9 is available!  To upgrade, please run:
wandb:  $ pip install wandb --upgrade
wandb: Tracking run with wandb version 0.12.17
wandb: Run data is saved locally in /home/qingyi/GPU20/DeepLOB/wandb/run-20240907_112229-2fanwu5r
wandb: Run `wandb offline` to turn off syncing.
wandb: Syncing run GRU
wandb: ⭐️ View project at https://wandb.ai/pqythu/futures500
wandb: 🚀 View run at https://wandb.ai/pqythu/futures500/runs/2fanwu5r
Model(
  (rnn): GRU(10, 64, batch_first=True)
  (fc): Linear(in_features=64, out_features=5, bias=True)
)
number of parameters: 14917
Training start
epoch  1 | time used:  1.09s | train_loss 1.492 | valid loss 1.489 | valid acc 0.328 | mae 2.022 | mse 6.825 | rmse 2.61 | r2 -1.50 | sharp 0.00
epoch  2 | time used:  0.18s | train_loss 1.490 | valid loss 1.489 | valid acc 0.328 | mae 2.022 | mse 6.825 | rmse 2.61 | r2 -1.50 | sharp 0.00
epoch  3 | time used:  0.17s | train_loss 1.494 | valid loss 1.521 | valid acc 0.315 | mae 1.978 | mse 6.645 | rmse 2.58 | r2 -1.43 | sharp 1.36
epoch  4 | time used:  0.18s | train_loss 1.477 | valid loss 1.489 | valid acc 0.328 | mae 2.022 | mse 6.825 | rmse 2.61 | r2 -1.50 | sharp 0.00
epoch  5 | time used:  0.20s | train_loss 1.481 | valid loss 1.486 | valid acc 0.328 | mae 2.022 | mse 6.825 | rmse 2.61 | r2 -1.50 | sharp 0.00
epoch  6 | time used:  0.17s | train_loss 1.459 | valid loss 1.489 | valid acc 0.328 | mae 2.022 | mse 6.825 | rmse 2.61 | r2 -1.50 | sharp 0.00
epoch  7 | time used:  0.17s | train_loss 1.484 | valid loss 1.521 | valid acc 0.315 | mae 1.978 | mse 6.645 | rmse 2.58 | r2 -1.43 | sharp 1.36
epoch  8 | time used:  0.19s | train_loss 1.484 | valid loss 1.521 | valid acc 0.315 | mae 1.978 | mse 6.645 | rmse 2.58 | r2 -1.43 | sharp 1.36
epoch  9 | time used:  0.19s | train_loss 1.490 | valid loss 1.490 | valid acc 0.328 | mae 2.022 | mse 6.825 | rmse 2.61 | r2 -1.50 | sharp 0.00
epoch 10 | time used:  0.16s | train_loss 1.481 | valid loss 1.489 | valid acc 0.328 | mae 2.022 | mse 6.825 | rmse 2.61 | r2 -1.50 | sharp 0.00
saving the model to ./save/2021_500/GRU/checkpoint10.pt
epoch 11 | time used:  0.15s | train_loss 1.485 | valid loss 1.490 | valid acc 0.328 | mae 2.022 | mse 6.825 | rmse 2.61 | r2 -1.50 | sharp 0.00
epoch 12 | time used:  0.15s | train_loss 1.490 | valid loss 1.521 | valid acc 0.315 | mae 1.978 | mse 6.645 | rmse 2.58 | r2 -1.43 | sharp 1.36
epoch 13 | time used:  0.15s | train_loss 1.488 | valid loss 1.489 | valid acc 0.328 | mae 2.022 | mse 6.825 | rmse 2.61 | r2 -1.50 | sharp 0.00
epoch 14 | time used:  0.15s | train_loss 1.480 | valid loss 1.490 | valid acc 0.328 | mae 2.022 | mse 6.825 | rmse 2.61 | r2 -1.50 | sharp 0.00
epoch 15 | time used:  0.19s | train_loss 1.491 | valid loss 1.489 | valid acc 0.328 | mae 2.022 | mse 6.825 | rmse 2.61 | r2 -1.50 | sharp 0.00
epoch 16 | time used:  0.18s | train_loss 1.481 | valid loss 1.479 | valid acc 0.328 | mae 2.022 | mse 6.825 | rmse 2.61 | r2 -1.50 | sharp 0.00
epoch 17 | time used:  0.20s | train_loss 1.483 | valid loss 1.490 | valid acc 0.328 | mae 2.022 | mse 6.825 | rmse 2.61 | r2 -1.50 | sharp 0.00
epoch 18 | time used:  0.16s | train_loss 1.487 | valid loss 1.489 | valid acc 0.328 | mae 2.022 | mse 6.825 | rmse 2.61 | r2 -1.50 | sharp 0.00
epoch 19 | time used:  0.17s | train_loss 1.482 | valid loss 1.521 | valid acc 0.315 | mae 1.978 | mse 6.645 | rmse 2.58 | r2 -1.43 | sharp 1.36
epoch 20 | time used:  0.17s | train_loss 1.486 | valid loss 1.489 | valid acc 0.328 | mae 2.022 | mse 6.825 | rmse 2.61 | r2 -1.50 | sharp 0.00
saving the model to ./save/2021_500/GRU/checkpoint20.pt
epoch 21 | time used:  0.17s | train_loss 1.479 | valid loss 1.489 | valid acc 0.328 | mae 2.022 | mse 6.825 | rmse 2.61 | r2 -1.50 | sharp 0.00
epoch 22 | time used:  0.17s | train_loss 1.484 | valid loss 1.521 | valid acc 0.315 | mae 1.978 | mse 6.645 | rmse 2.58 | r2 -1.43 | sharp 1.36
epoch 23 | time used:  0.15s | train_loss 1.462 | valid loss 1.489 | valid acc 0.328 | mae 2.022 | mse 6.825 | rmse 2.61 | r2 -1.50 | sharp 0.00
epoch 24 | time used:  0.14s | train_loss 1.486 | valid loss 1.489 | valid acc 0.328 | mae 2.022 | mse 6.825 | rmse 2.61 | r2 -1.50 | sharp 0.00
epoch 25 | time used:  0.16s | train_loss 1.483 | valid loss 1.486 | valid acc 0.328 | mae 2.022 | mse 6.825 | rmse 2.61 | r2 -1.50 | sharp 0.00
epoch 26 | time used:  0.15s | train_loss 1.484 | valid loss 1.489 | valid acc 0.328 | mae 2.022 | mse 6.825 | rmse 2.61 | r2 -1.50 | sharp 0.00
epoch 27 | time used:  0.15s | train_loss 1.477 | valid loss 1.521 | valid acc 0.315 | mae 1.978 | mse 6.645 | rmse 2.58 | r2 -1.43 | sharp 1.36
epoch 28 | time used:  0.16s | train_loss 1.491 | valid loss 1.489 | valid acc 0.328 | mae 2.022 | mse 6.825 | rmse 2.61 | r2 -1.50 | sharp 0.00
epoch 29 | time used:  0.18s | train_loss 1.486 | valid loss 1.489 | valid acc 0.328 | mae 2.022 | mse 6.825 | rmse 2.61 | r2 -1.50 | sharp 0.00
epoch 30 | time used:  0.17s | train_loss 1.483 | valid loss 1.489 | valid acc 0.328 | mae 2.022 | mse 6.825 | rmse 2.61 | r2 -1.50 | sharp 0.00
saving the model to ./save/2021_500/GRU/checkpoint30.pt
epoch 31 | time used:  0.15s | train_loss 1.478 | valid loss 1.521 | valid acc 0.315 | mae 1.978 | mse 6.645 | rmse 2.58 | r2 -1.43 | sharp 1.36
epoch 32 | time used:  0.15s | train_loss 1.487 | valid loss 1.521 | valid acc 0.315 | mae 1.978 | mse 6.645 | rmse 2.58 | r2 -1.43 | sharp 1.36
epoch 33 | time used:  0.15s | train_loss 1.479 | valid loss 1.489 | valid acc 0.328 | mae 2.022 | mse 6.825 | rmse 2.61 | r2 -1.50 | sharp 0.00
epoch 34 | time used:  0.16s | train_loss 1.473 | valid loss 1.489 | valid acc 0.328 | mae 2.022 | mse 6.825 | rmse 2.61 | r2 -1.50 | sharp 0.00
epoch 35 | time used:  0.15s | train_loss 1.479 | valid loss 1.489 | valid acc 0.328 | mae 2.022 | mse 6.825 | rmse 2.61 | r2 -1.50 | sharp 0.00
epoch 36 | time used:  0.17s | train_loss 1.690 | valid loss 1.489 | valid acc 0.328 | mae 2.022 | mse 6.825 | rmse 2.61 | r2 -1.50 | sharp 0.00
epoch 37 | time used:  0.19s | train_loss 1.498 | valid loss 1.521 | valid acc 0.315 | mae 1.978 | mse 6.645 | rmse 2.58 | r2 -1.43 | sharp 1.36
epoch 38 | time used:  0.17s | train_loss 1.472 | valid loss 1.488 | valid acc 0.328 | mae 2.022 | mse 6.825 | rmse 2.61 | r2 -1.50 | sharp 0.00
epoch 39 | time used:  0.19s | train_loss 1.484 | valid loss 1.520 | valid acc 0.315 | mae 1.978 | mse 6.645 | rmse 2.58 | r2 -1.43 | sharp 1.36
epoch 40 | time used:  0.17s | train_loss 1.480 | valid loss 1.521 | valid acc 0.315 | mae 1.978 | mse 6.645 | rmse 2.58 | r2 -1.43 | sharp 1.36
saving the model to ./save/2021_500/GRU/checkpoint40.pt
